<?xml version="1.0"?>
<robot xmlns:xacro="http://www.ros.org/wiki/xacro"  name="robot">

    <!--Inserindo o arquivo de inercia-->
    <xacro:include filename="inertial_macros.xacro"/>

    <!--Colocando cores atraves das seguintes tags-->
    <material name="white">
        <color rgba="1 1 1 1"/>
    </material>

    <material name="orange">
        <color rgba="1 0.3 0.1 1"/>
    </material>

    <material name="blue">
        <color rgba="0.2 0.2 1 1"/>
    </material>

    <material name="black">
        <color rgba="0 0 0 1"/>
    </material>


    <!-- ===================== BASE LINK ===================== -->
    <!--Função padrão para executar um robot diferencial-->
    <link name="base_link">

    </link>
    
    <!-- ===================== CHASSIS LINK ===================== -->

    <!--Comandos para fazer a conexao e declarar o tipos-->
    <joint name="chassis_joint" type="fixed">
        <!--Criando hierarquia dos links futuros-->
        <parent link="base_link"/>
        <child link="chassis"/>
        <origin xyz="-0.1 0 0"/>
    </joint>

    <!--Criando links que sao responsaveis pela estrutura do robo-->
    <link name="chassis">
        <visual>
            <origin xyz="0.15 0 0.075"/>
            <geometry>
                <box size="0.3 0.3 0.15"/> <!--Tamanho e estrutura do robo (mm)-->
            </geometry>

            <material name="white"/> 
        </visual>

        <!--Parte que possui o contato no simulador real -->
        <collision>
            <origin xyz="0.15 0 0.075" rpy="0 0 0"/>
            <geometry>
                <box size="0.3 0.3 0.15"/>
            </geometry>
        </collision>

        <xacro:inertial_box mass="0.5" x="0.3" y="0.3" z="0.15">
            <origin xyz="0.15 0 0.075" rpy="0 0 0"/>
        </xacro:inertial_box>

    </link>

    <!--Adicionando cores para o gazebo-->
    <gazebo reference="chassis">
        <material>Gazebo/Yellow</material>
    </gazebo>

    <!-- ===================== LEFT WHEEL LINK ===================== -->
    <joint name="left_wheel_joint" type="continuous">
        <parent link="base_link"/>
        <child link="left_wheel"/>
        <origin xyz="0 0.175 0" rpy="-${pi/2} 0 0"/>
        <axis xyz="0 0 1"/>
    </joint>

    <link name="left_wheel">
        <visual>
            <geometry>
                <cylinder length="0.04" radius="0.05" />
            </geometry>
            <material name="blue"/>
        </visual>

        <collision>
            <geometry>
                <cylinder length="0.04" radius="0.05" />
            </geometry>
            <material name="blue"/>
        </collision>

        <xacro:inertial_cylinder mass="0.1" length="0.05" radius="0.05">
            <origin xyz="0 0 0" rpy="0 0 0"/>
        </xacro:inertial_cylinder>

    </link>

    <gazebo reference="left_wheel">
        <material>Gazebo/Blue</material>
    </gazebo>

    <!-- ===================== RIGHT WHEEL LINK ===================== -->

    <joint name="right_wheel_joint" type="continuous">
        <parent link="base_link"/>
        <child link="right_wheel"/>
        <origin xyz="0 -0.175 0" rpy="${pi/2} 0 0"/>
        <axis xyz="0 0 -1"/>
    </joint>

    <link name="right_wheel">
        <visual>
            <geometry>
                <cylinder length="0.04" radius="0.05" />
            </geometry>
            <material name="blue"/>
        </visual>

        <collision>
            <geometry>
                <cylinder length="0.04" radius="0.05" />
            </geometry>
            <material name="blue"/>
        </collision>

        <xacro:inertial_sphere mass="0.1" radius="0.05">
            <origin xyz="0 0 0" rpy="0 0 0"/>
        </xacro:inertial_sphere>

    </link>

    <gazebo reference="right_wheel">
        <material>Gazebo/Blue</material>
    </gazebo>

    <!-- ===================== CASTER WHEEL LINK ===================== -->

    <joint name="caster_wheel_joint" type="fixed">
        <parent link="chassis"/>
        <child link="caster_wheel"/>
        <origin xyz="0.24 0 0" rpy="0 0 0"/>
    </joint>

    <link name="caster_wheel">
        <visual>
            <geometry>
                <sphere radius="0.05" /> <!--sphere = esfera-->
            </geometry>
            <material name="black"/>
        </visual>

        <collision>
            <geometry>
                <sphere radius="0.05" /> 
            </geometry>
            <material name="black"/>
        </collision>

        <xacro:inertial_sphere mass="0.1" radius="0.05">
            <origin xyz="0 0 0" rpy="0 0 0"/>
        </xacro:inertial_sphere>

    </link> 

    <gazebo reference="caster_wheel">
        <material>Gazebo/Red</material>
        <!--(Reduzindo o atrito) para que a esfera possa girar -->
        <mu1 value="0.001"/>
        <mu2 value="0.001"/>
    </gazebo>       

</robot>

